2025-07-24 18:02:16,744 INFO    MainThread:30414 [wandb_setup.py:_flush():80] Current SDK version is 0.21.0
2025-07-24 18:02:16,744 INFO    MainThread:30414 [wandb_setup.py:_flush():80] Configure stats pid to 30414
2025-07-24 18:02:16,745 INFO    MainThread:30414 [wandb_setup.py:_flush():80] Loading settings from /root/.config/wandb/settings
2025-07-24 18:02:16,745 INFO    MainThread:30414 [wandb_setup.py:_flush():80] Loading settings from /root/autodl-tmp/T2VUnlearning/wandb/settings
2025-07-24 18:02:16,745 INFO    MainThread:30414 [wandb_setup.py:_flush():80] Loading settings from environment variables
2025-07-24 18:02:16,745 INFO    MainThread:30414 [wandb_init.py:setup_run_log_directory():703] Logging user logs to /root/autodl-tmp/T2VUnlearning/wandb/run-20250724_180216-ufmkzfib/logs/debug.log
2025-07-24 18:02:16,745 INFO    MainThread:30414 [wandb_init.py:setup_run_log_directory():704] Logging internal logs to /root/autodl-tmp/T2VUnlearning/wandb/run-20250724_180216-ufmkzfib/logs/debug-internal.log
2025-07-24 18:02:16,745 INFO    MainThread:30414 [wandb_init.py:init():830] calling init triggers
2025-07-24 18:02:16,745 INFO    MainThread:30414 [wandb_init.py:init():835] wandb.init called with sweep_config: {}
config: {'concept': 'nudity', 'prompt_path': '/root/autodl-tmp/T2VUnlearning/evaluation/data/nudity-ring-a-bell.csv', 'image_or_video_path': None, 'model_path': '/root/autodl-tmp/models/cogvideox-2b', 'eraser_ckpt_path': '/root/autodl-tmp/T2VUnlearning/adapter/self_cogvideox2b_nudity_erasure', 'eraser_rank': 128, 'num_inference_steps': 50, 'num_frames': 17, 'generate_type': 't2v', 'dtype': 'float16', 'num_epoch': 2, 'seed': 42, '_wandb': {}}
2025-07-24 18:02:16,745 INFO    MainThread:30414 [wandb_init.py:init():871] starting backend
2025-07-24 18:02:16,953 INFO    MainThread:30414 [wandb_init.py:init():874] sending inform_init request
2025-07-24 18:02:16,960 INFO    MainThread:30414 [wandb_init.py:init():882] backend started and connected
2025-07-24 18:02:16,961 INFO    MainThread:30414 [wandb_init.py:init():953] updated telemetry
2025-07-24 18:02:16,965 INFO    MainThread:30414 [wandb_init.py:init():977] communicating run to backend with 90.0 second timeout
2025-07-24 18:02:48,082 INFO    Thread-1 (wrapped_target):30414 [retry.py:__call__():173] [no run ID] Retry attempt failed:
Traceback (most recent call last):
  File "/root/miniconda3/envs/eraser/lib/python3.10/site-packages/urllib3/connection.py", line 198, in _new_conn
    sock = connection.create_connection(
  File "/root/miniconda3/envs/eraser/lib/python3.10/site-packages/urllib3/util/connection.py", line 85, in create_connection
    raise err
  File "/root/miniconda3/envs/eraser/lib/python3.10/site-packages/urllib3/util/connection.py", line 73, in create_connection
    sock.connect(sa)
TimeoutError: timed out

The above exception was the direct cause of the following exception:

Traceback (most recent call last):
  File "/root/miniconda3/envs/eraser/lib/python3.10/site-packages/urllib3/connectionpool.py", line 787, in urlopen
    response = self._make_request(
  File "/root/miniconda3/envs/eraser/lib/python3.10/site-packages/urllib3/connectionpool.py", line 488, in _make_request
    raise new_e
  File "/root/miniconda3/envs/eraser/lib/python3.10/site-packages/urllib3/connectionpool.py", line 464, in _make_request
    self._validate_conn(conn)
  File "/root/miniconda3/envs/eraser/lib/python3.10/site-packages/urllib3/connectionpool.py", line 1093, in _validate_conn
    conn.connect()
  File "/root/miniconda3/envs/eraser/lib/python3.10/site-packages/urllib3/connection.py", line 753, in connect
    self.sock = sock = self._new_conn()
  File "/root/miniconda3/envs/eraser/lib/python3.10/site-packages/urllib3/connection.py", line 207, in _new_conn
    raise ConnectTimeoutError(
urllib3.exceptions.ConnectTimeoutError: (<urllib3.connection.HTTPSConnection object at 0x7fae1d52a650>, 'Connection to api.wandb.ai timed out. (connect timeout=20)')

The above exception was the direct cause of the following exception:

Traceback (most recent call last):
  File "/root/miniconda3/envs/eraser/lib/python3.10/site-packages/requests/adapters.py", line 667, in send
    resp = conn.urlopen(
  File "/root/miniconda3/envs/eraser/lib/python3.10/site-packages/urllib3/connectionpool.py", line 841, in urlopen
    retries = retries.increment(
  File "/root/miniconda3/envs/eraser/lib/python3.10/site-packages/urllib3/util/retry.py", line 519, in increment
    raise MaxRetryError(_pool, url, reason) from reason  # type: ignore[arg-type]
urllib3.exceptions.MaxRetryError: HTTPSConnectionPool(host='api.wandb.ai', port=443): Max retries exceeded with url: /graphql (Caused by ConnectTimeoutError(<urllib3.connection.HTTPSConnection object at 0x7fae1d52a650>, 'Connection to api.wandb.ai timed out. (connect timeout=20)'))

During handling of the above exception, another exception occurred:

Traceback (most recent call last):
  File "/root/miniconda3/envs/eraser/lib/python3.10/site-packages/wandb/sdk/lib/retry.py", line 134, in __call__
    result = self._call_fn(*args, **kwargs)
  File "/root/miniconda3/envs/eraser/lib/python3.10/site-packages/wandb/sdk/internal/internal_api.py", line 397, in execute
    return self.client.execute(*args, **kwargs)  # type: ignore
  File "/root/miniconda3/envs/eraser/lib/python3.10/site-packages/wandb/vendor/gql-0.2.0/wandb_gql/client.py", line 52, in execute
    result = self._get_result(document, *args, **kwargs)
  File "/root/miniconda3/envs/eraser/lib/python3.10/site-packages/wandb/vendor/gql-0.2.0/wandb_gql/client.py", line 60, in _get_result
    return self.transport.execute(document, *args, **kwargs)
  File "/root/miniconda3/envs/eraser/lib/python3.10/site-packages/wandb/sdk/lib/gql_request.py", line 58, in execute
    request = self.session.post(self.url, **post_args)
  File "/root/miniconda3/envs/eraser/lib/python3.10/site-packages/requests/sessions.py", line 637, in post
    return self.request("POST", url, data=data, json=json, **kwargs)
  File "/root/miniconda3/envs/eraser/lib/python3.10/site-packages/requests/sessions.py", line 589, in request
    resp = self.send(prep, **send_kwargs)
  File "/root/miniconda3/envs/eraser/lib/python3.10/site-packages/requests/sessions.py", line 703, in send
    r = adapter.send(request, **kwargs)
  File "/root/miniconda3/envs/eraser/lib/python3.10/site-packages/requests/adapters.py", line 688, in send
    raise ConnectTimeout(e, request=request)
requests.exceptions.ConnectTimeout: HTTPSConnectionPool(host='api.wandb.ai', port=443): Max retries exceeded with url: /graphql (Caused by ConnectTimeoutError(<urllib3.connection.HTTPSConnection object at 0x7fae1d52a650>, 'Connection to api.wandb.ai timed out. (connect timeout=20)'))
